2024-11-17 02:08:58 - INFO - Validating database connection...
2024-11-17 02:08:58 - ERROR - 
Critical error occurred: Database connection failed: connection failed: connection to server at "127.0.0.1", port 5432 failed: FATAL:  database "datathon" does not exist
2024-11-17 02:08:58 - ERROR - Traceback (most recent call last):
  File "/home/omar/.pyenv/versions/3.12.2/lib/python3.12/site-packages/django/db/backends/base/base.py", line 279, in ensure_connection
    self.connect()
  File "/home/omar/.pyenv/versions/3.12.2/lib/python3.12/site-packages/django/utils/asyncio.py", line 26, in inner
    return func(*args, **kwargs)
           ^^^^^^^^^^^^^^^^^^^^^
  File "/home/omar/.pyenv/versions/3.12.2/lib/python3.12/site-packages/django/db/backends/base/base.py", line 256, in connect
    self.connection = self.get_new_connection(conn_params)
                      ^^^^^^^^^^^^^^^^^^^^^^^^^^^^^^^^^^^^
  File "/home/omar/.pyenv/versions/3.12.2/lib/python3.12/site-packages/django/utils/asyncio.py", line 26, in inner
    return func(*args, **kwargs)
           ^^^^^^^^^^^^^^^^^^^^^
  File "/home/omar/.pyenv/versions/3.12.2/lib/python3.12/site-packages/django/db/backends/postgresql/base.py", line 332, in get_new_connection
    connection = self.Database.connect(**conn_params)
                 ^^^^^^^^^^^^^^^^^^^^^^^^^^^^^^^^^^^^
  File "/home/omar/.pyenv/versions/3.12.2/lib/python3.12/site-packages/psycopg/connection.py", line 119, in connect
    raise last_ex.with_traceback(None)
psycopg.OperationalError: connection failed: connection to server at "127.0.0.1", port 5432 failed: FATAL:  database "datathon" does not exist

The above exception was the direct cause of the following exception:

Traceback (most recent call last):
  File "/home/omar/datathon/backend/algoritmo dos/main_test.py", line 13, in validate_database_connection
    connection.ensure_connection()
  File "/home/omar/.pyenv/versions/3.12.2/lib/python3.12/site-packages/django/utils/asyncio.py", line 26, in inner
    return func(*args, **kwargs)
           ^^^^^^^^^^^^^^^^^^^^^
  File "/home/omar/.pyenv/versions/3.12.2/lib/python3.12/site-packages/django/db/backends/base/base.py", line 278, in ensure_connection
    with self.wrap_database_errors:
  File "/home/omar/.pyenv/versions/3.12.2/lib/python3.12/site-packages/django/db/utils.py", line 91, in __exit__
    raise dj_exc_value.with_traceback(traceback) from exc_value
  File "/home/omar/.pyenv/versions/3.12.2/lib/python3.12/site-packages/django/db/backends/base/base.py", line 279, in ensure_connection
    self.connect()
  File "/home/omar/.pyenv/versions/3.12.2/lib/python3.12/site-packages/django/utils/asyncio.py", line 26, in inner
    return func(*args, **kwargs)
           ^^^^^^^^^^^^^^^^^^^^^
  File "/home/omar/.pyenv/versions/3.12.2/lib/python3.12/site-packages/django/db/backends/base/base.py", line 256, in connect
    self.connection = self.get_new_connection(conn_params)
                      ^^^^^^^^^^^^^^^^^^^^^^^^^^^^^^^^^^^^
  File "/home/omar/.pyenv/versions/3.12.2/lib/python3.12/site-packages/django/utils/asyncio.py", line 26, in inner
    return func(*args, **kwargs)
           ^^^^^^^^^^^^^^^^^^^^^
  File "/home/omar/.pyenv/versions/3.12.2/lib/python3.12/site-packages/django/db/backends/postgresql/base.py", line 332, in get_new_connection
    connection = self.Database.connect(**conn_params)
                 ^^^^^^^^^^^^^^^^^^^^^^^^^^^^^^^^^^^^
  File "/home/omar/.pyenv/versions/3.12.2/lib/python3.12/site-packages/psycopg/connection.py", line 119, in connect
    raise last_ex.with_traceback(None)
django.db.utils.OperationalError: connection failed: connection to server at "127.0.0.1", port 5432 failed: FATAL:  database "datathon" does not exist

During handling of the above exception, another exception occurred:

Traceback (most recent call last):
  File "/home/omar/datathon/backend/algoritmo dos/main_test.py", line 44, in main
    validate_database_connection()
  File "/home/omar/datathon/backend/algoritmo dos/main_test.py", line 19, in validate_database_connection
    raise Exception(f"Database connection failed: {str(e)}")
Exception: Database connection failed: connection failed: connection to server at "127.0.0.1", port 5432 failed: FATAL:  database "datathon" does not exist

